Workbook

Sheet Cover Page
A4: Subsurface Drip Irrigation Design Tool
A12: Contact Information
D13: P.O. Box 77457
D14: Greensboro, NC 27417
D15: T 800.828.3388
D16: e customerservice@geoflow.com
D17: w geoflow.com
G18: ©2023 Geoflow

Sheet Step 1 - Design Inputs
A3: Small Systems Design Sheet
A5: Directions: Fill-in applicable cells in BLACK. Answers appear in PURPLE. | H5: ©2023 Geoflow | J5: v.230721
A7: 1050 | B7: gpd, maximum flow | E7: Definitions: | F7: 1. Day = 24 hours
A8: 0.2 | B8: gpd/ft2, soil loading rate | F8: 2. Lateral = supply to return connection total length
A9: 1 | B9: usuable acres for dispersal | F9: 3. Run = number and length within each lateral
A10: =A7/A8 -> 5250 | B10: ft2, total
A11: =(A10/43560)/A9 -> 0.12052342 | B11: acres, minimum
A12: G-WFPC-16-2-24-PRO | B12: drip tubing p/n
A13: 2 | B13: ft, dripline spacing
A14: =A10/A13 -> 2625 | B14: ft, dripline required
A15: =LOOKUP(A12,Table24[Drip Tube Model '#],Table24[Emitter Spacing Feet]) -> 2 | B15: ft, dripper (emitter) spacing
A16: =A15*A13 -> 4 | B16: ft2 per dripper
A17: =A16*A8 -> 0.8 | B17: gpd dispersed, per dripper
A18: =LOOKUP(A12,Table24[Drip Tube Model '#],Table24[Nominal Emitter Flow GPH]) -> 0.6 | B18: gph, per dripper rate
A19: =A17/A18 -> 1.3333333 | B19: hrs/d, theoretical per dripper max run time
A20: =A19*60 -> 80 | B20: min/d, theoretical per dripper max run time
A21: 12 | B21: max hrs/d, pump run time (12 hrs default)
A22: =A21/A19 -> 9 | B22: max theoretical zones, no.
A23: 1 | B23: select number of zones
A25: =A10/A23 -> 5250 | B25: ft2, each zone | F25: Yes
A26: =A14/A23 -> 2625 | B26: ft, theoretical dripline run length per zone | F26: No
A27: No | B27: drip lateral length >10% (shortest to longest) | F27: CONTACT GEOFLOW ENGINEERING 800.828.3388
A28: 202 | B28: ft, lateral length | E28: =IF(A15=1,IF(A28<=150,TRUE,FALSE),IF(A15=2,IF(A28<=300,TRUE,FALSE))) -> TRUE | F28: =IF(A27="No",IF(E28=TRUE,TRUE,FALSE)) -> TRUE
A29: 13 | B29: select laterals per zone
A30: 0.5 | B30: fps, flush velocity
A31: =A28*A29 -> 2626 | B31: ft, calculated dripline run length per zone | F31: =IF(A26>A31,"CALCULATED < THEORETICAL; ADJUST LENGTH!",FALSE) -> FALSE
A32: =(A31/A15) -> 1313 | B32: drippers, calculated per zone
A33: =A29*A28/A15*A18/60 -> 13.13 | B33: gpm, dispersal flow rate
A34: =A30/0.4085*0.55^2*A29+A33 -> 17.943341 | B34: gpm, flushing flow rate
A35: =A34-A33 -> 4.8133415 | B35: gpm, return flow rate
A37: 12 | B37: input cycles per day per zone, no. (all zones dosed invidually each cycle)
A38: =(A7/(A23*A33))/A37 -> 6.664128 | B38: min, run time (fully pressurized) per zone per dose
A39: =A23*A38 -> 6.664128 | B39: min, "on" time per dose cycle
A40: =(1440/A37)-A39 -> 113.33587 | B40: min, "off" time per dose cycle | F40: CONTACT GEOFLOW ENGINEERING 800.828.3388
A41: =A39*A37 -> 79.969535 | B41: min/d, "on" time, or | D41: =A41/60 -> 1.3328256 | E41: hrs/d
A42: =A40*A37 -> 1360.0305 | B42: min/d, "off" time, or | D42: =A42/60 -> 22.667174 | E42: hrs/d | F42: CONTACT GEOFLOW ENGINEERING 800.828.3388
A43: =A38*A33*A23 -> 87.5 | B43: field dose volume, gal
A44: =3*A23*A34 -> 53.830024 | B44: field flush volume, gal (@ 3 min end cycle)
A45: =(A38-3)*(A33*A23)+A44 -> 101.94002 | B45: total field flush volume, gal
A46: =A33*2 -> 26.26 | B46: filter flush volume, gal (allows for two back-to-back flushes)
...

Sheet System Layout
A4: System Layout
D5: 1 - Headworks to flush discharge point
D6: 2 - Headworks
D7: 3 - Return manifold outlet to headworks
D8: 4 - Drip lateral length return manidold to supply manifold
D9: 5 - Supply manifold to zone valve (if zone valve used)
D10: 6 - Zone valve, if used
D11: 7 - Headworks to zone valve/supply manifold
D12: 8 - Headworks
D13: 9 - Pump discharge to headworks
K39: ©2023 Geoflow

Sheet Step 3 - Zone TDH
A3: G-WFPC-16-4-12-PRO | B3: Drip Tube | L3: ©2023 Geoflow | N3: v.230721
A4: G-WHWRS-D150A | B4: Headworks
A5: 1 Zone | B5: Zone Valve
A6: 2 | B6: Flushing Velocity
A7: 20 | B7: Maximum Inlet Pressure
A8: 20 | B8: Minimum Outlet Pressure
A9: 126 | B9: Longest Lateral
A10: 2 | B10: Total Number of Laterals
A11: =A10*A9 -> 252 | B11: Total Linear Footage of Drip Tube
B13: Pipe Diameter Inches | C13: Linear Feet | D13: Elevation Feet | E13: Dispersal GPM | F13: Flushing GPM | G13: Return GPM | H13: Dispersal Velocity | I13: Flushing Velocity | J13: Return Velocity | K13: Dispersal F Loss PSI | L13: Flushing F Loss PSI | M13: Elevation PSI | N13: Total Q Gallons
A14: 1. Headworks to flush discharge point | B14: 1 | C14: 20 | D14: -5 | G14: ='Drip Tube Data'!$C$36 -> 2.9620563 | J14: =0.4085*G14/(LOOKUP($B$14,Table5[OD Inches],Table5[ID Inches]))^2 -> 1.0995991 | L14: =0.2083*(100/$A$36)^1.852*G14^1.852/LOOKUP(B14,Table5[OD Inches],Table5[ID Inches])^4.866*0.433*'Step 3 - Zone TDH'!C14/100+M14 -> -2.1146055 | M14: =D14*0.433 -> -2.165 | N14: =C14*0.04079905*LOOKUP(B14,Table5[OD Inches],Table5[ID Inches])^2 -> 0.89790631
A15: 2 - Headworks | G15: ='Drip Tube Data'!$C$36 -> 2.9620563 | L15: =LOOKUP(A4,'Headworks Data'!B15:G15,'Headworks Data'!B18:G18) -> 4.6
A16: 3 - Return manifold outlet to headworks | B16: 1 | C16: 140 | D16: -5 | G16: ='Drip Tube Data'!$C$36 -> 2.9620563 | J16: =0.4085*G16/(LOOKUP($B$16,Table5[OD Inches],Table5[ID Inches]))^2 -> 1.0995991 | L16: =0.2083*(100/$A$36)^1.852*G16^1.852/LOOKUP(B16,Table5[OD Inches],Table5[ID Inches])^4.866*0.433*'Step 3 - Zone TDH'!C16/100+M16 -> -1.8122383 | M16: =D16*0.433 -> -2.165 | N16: =C16*0.04079905*LOOKUP(B16,Table5[OD Inches],Table5[ID Inches])^2 -> 6.2853442
A17: 4 - Drip lateral supply manidold to return manifold | E17: ='Drip Tube Data'!C32 -> 1.89 | F17: ='Drip Tube Data'!C34 -> 3.3710282 | G17: =F17-E17 -> 1.4810282 | I17: =A6 -> 2 | K17: =LOOKUP('Step 3 - Zone TDH'!A9,'Drip Tube Loss Calculator'!A26:A300,'Drip Tube Loss Calculator'!K26:K300) -> 5.2655454 | L17: =LOOKUP('Step 3 - Zone TDH'!A9,'Drip Tube Loss Calculator'!A26:A300,'Drip Tube Loss Calculator'!Y26:Y300) -> 26.386671 | N17: =A9*'Drip Tube Data'!G29 -> 1.5550558
A18: 5 - Zone valve (if zone valve used) to supply manifold | B18: 1 | C18: 0 | D18: 0 | E18: ='Drip Tube Data'!C33 -> 3.78 | F18: ='Drip Tube Data'!C35 -> 6.7420563 | H18: =0.4085*E18/(LOOKUP($B18,'Pipe Data'!B4:B12,Table5[ID Inches]))^2 -> 1.403243 | I18: =0.4085*F18/(LOOKUP($B18,Table5[OD Inches],Table5[ID Inches]))^2 -> 2.5028421 | K18: =0.2083*(100/$A$36)^1.852*E18^1.852/LOOKUP(B18,Table5[OD Inches],Table5[ID Inches])^4.866*0.433*'Step 3 - Zone TDH'!C18/100+M18 -> 0 | L18: =0.2083*(100/$A$36)^1.852*F18^1.852/LOOKUP(B18,Table5[OD Inches],Table5[ID Inches])^4.866*0.433*'Step 3 - Zone TDH'!C18/100+M18 -> 0 | M18: =D18*0.433 -> 0 | N18: =C18*0.04079905*LOOKUP(B18,Table5[OD Inches],Table5[ID Inches])^2 -> 0
A19: 6 - Zone valve, if used | K19: =LOOKUP(A5,Table1[#Headers],'Zone Valves Data'!C8:M8) -> 0 | L19: =LOOKUP(A5,Table1[#Headers],'Zone Valves Data'!C9:M9) -> 0
A20: 7 - Headworks to zone valve/supply manifold | B20: 1 | C20: 140 | D20: 5 | E20: ='Drip Tube Data'!$C$33 -> 3.78 | F20: ='Drip Tube Data'!$C$35 -> 6.7420563 | H20: =0.4085*E20/(LOOKUP($B20,Table5[OD Inches],Table5[ID Inches]))^2 -> 1.403243 | I20: =0.4085*F20/(LOOKUP($B20,Table5[OD Inches],Table5[ID Inches]))^2 -> 2.5028421 | K20: =0.2083*(100/$A$36)^1.852*E20^1.852/LOOKUP(B20,Table5[OD Inches],Table5[ID Inches])^4.866*0.433*'Step 3 - Zone TDH'!C20/100+M20 -> 2.7191221 | L20: =0.2083*(100/$A$36)^1.852*F20^1.852/LOOKUP(B20,Table5[OD Inches],Table5[ID Inches])^4.866*0.433*'Step 3 - Zone TDH'!C20/100+M20 -> 3.7831327 | M20: =D20*0.433 -> 2.165 | N20: =C20*0.04079905*LOOKUP(B20,Table5[OD Inches],Table5[ID Inches])^2 -> 6.2853442
A21: 8 - Headworks | E21: ='Drip Tube Data'!$C$33 -> 3.78 | F21: ='Drip Tube Data'!C34 -> 3.3710282 | K21: =LOOKUP(A4,'Headworks Data'!B15:G15,'Headworks Data'!B16:G16) -> 5.64 | L21: =LOOKUP(A4,'Headworks Data'!B15:G15,'Headworks Data'!B17:G17) -> 6.3
A22: 9 - Pump discharge to headworks | B22: 1 | C22: 20 | D22: 5 | E22: ='Drip Tube Data'!$C$33 -> 3.78 | F22: ='Drip Tube Data'!C35 -> 6.7420563 | H22: =0.4085*E22/(LOOKUP(B22,Table5[OD Inches],Table5[ID Inches]))^2 -> 1.403243 | I22: =0.4085*F22/(LOOKUP($B$22,Table5[OD Inches],Table5[ID Inches]))^2 -> 2.5028421 | K22: =0.2083*(100/$A$36)^1.852*E22^1.852/LOOKUP(B22,Table5[OD Inches],Table5[ID Inches])^4.866*0.433*'Step 3 - Zone TDH'!C22/100+M22 -> 2.2441603 | L22: =0.2083*(100/$A$36)^1.852*F22^1.852/LOOKUP(B22,Table5[OD Inches],Table5[ID Inches])^4.866*0.433*'Step 3 - Zone TDH'!C22/100+M22 -> 2.3961618 | M22: =D22*0.433 -> 2.165 | N22: =C22*0.04079905*LOOKUP(B22,Table5[OD Inches],Table5[ID Inches])^2 -> 0.89790631
A24: 1 | B24: Headworks to flush discharge point | H24: 6 | I24: Zone valve, if used
A25: 2 | B25: Headworks | H25: 7 | I25: Headworks to Zone valve/supply manifold
A26: 3 | B26: Return manifold outlet to headworks | H26: 8 | I26: Headworks
A27: 4 | B27: Drip lateral supply manidold to return manifold | H27: 9 | I27: Headworks to Zone valve/supply manifold
A28: 5 | B28: Zone valve (if zone valve used) to supply manifold
A30: =MAX(E14:E22) -> 3.78 | B30: GPM, Minimum Required During Dispersal Cycle
A31: =A7+((SUM(K17:K22))*A37) -> 37.455711 | B31: PSI, Minimum Pressure During Dispersal Cycle at Pump Discharge | H31: =A31*2.31 -> 86.522691 | I31: Feet, Minimum Pressure During Dispersal Cycle at Pump Discharge
A32: =MAX(F14:F22) -> 6.7420563 | B32: GPM, Minimum Required During Flushing Cycle
A33: =A7+((SUM(L14:L22))*A37) -> 63.493034 | B33: PSI, Minimum Pressure During Flushing Cycle at Pump Discharge | H33: =A33*2.31 -> 146.66891 | I33: Feet, Minimum Pressure During Flushing Cycle at Pump Discharge
A34: =SUM(N14:N22)-N17+(A11*'Drip Tube Data'!G29) -> 17.476613 | B34: Gallons, Minimum Required to Fill Pipe Network
A36: 150 | B36: Pipe coefficient is a value that reflects the roughness of the inside of a pipe, 150 is standard for PVC and is used in this calculator.
A37: 1.1 | B37: Error factor is an adjustment value to account for fittings, bends, and miscellaneous losses associated with pipe systems. 1.1 is commonly used in the irrigation industry and is used here.
A38: ↓ | B38: Click in the cells with the arrow on right and select from the dropdown menu.
A39: SAMPLE TEXT | B39: Fill-in applicable cells in BLACK. See the heading of each cell, all other cell are self populating.
B40: The loss columns indicate the loss in psi due to friction of the water as it flows through the pipe network as well as the increase or decrease due to elevation.
B41: Velocity is measure of how fast water is moving through a given section of pipe, expressed in fps. When designing transport lines, the target flushing velocity is 2.5 to 3.5 fps or per state requirements. Properly sized pipes shorten fill time, increase dispersal uniformity, and aide in overall system operation and maintenance. This spreadsheet calculates the velocity based on your inputs.
B43: TURBINE PUMPS
B44: ='Pump Data'!B8 -> Little Giant | C44: ='Pump Data'!C8 -> Blaster | D44: ='Pump Data'!D8 -> Ashland CPM | E44: ='Pump Data'!E8:I8 -> Zoeller
A45: MODEL | B45: ='Pump Data'!B9 -> 20XC1-05P4 | C45: ='Pump Data'!C9 -> 20EB05 | D45: ='Pump Data'!D9 -> 20+ 1/2hp | E45: ='Pump Data'!E9 -> 5030 7S-1/2hp | F45: ='Pump Data'!F9 -> 5031 5S-1/2hp | G45: ='Pump Data'!G9 -> 5031 9S-1hp | H45: ='Pump Data'!H9 -> 5032 4S-1/2hp | I45: ='Pump Data'!I9 -> 5032 7S-1hp
A46: DOSING TDH | B46: ='Pump Data'!B13 -> 163.2 | C46: ='Pump Data'!C13 -> 154.4 | D46: ='Pump Data'!D13 -> 164 | E46: ='Pump Data'!E13 -> 235 | F46: ='Pump Data'!F13 -> 154 | G46: ='Pump Data'!G13 -> 269 | H46: ='Pump Data'!H13 -> 119.6 | I46: ='Pump Data'!I13 -> 220.8
A47: FLUSHING TDH | B47: ='Pump Data'!B14 -> 157.4 | C47: ='Pump Data'!C14 -> 150.6 | D47: ='Pump Data'!D14 -> 157.4 | E47: ='Pump Data'!E14 -> 220 | F47: ='Pump Data'!F14 -> 148 | G47: ='Pump Data'!G14 -> 261 | H47: ='Pump Data'!H14 -> NO | I47: ='Pump Data'!I14 -> 219.2

Sheet Pump Data
A3: 1 | B3: ='Step 3 - Zone TDH'!A30 -> 3.78 | C3: GPM, Minimum Required During Dispersal Cycle
A4: 2 | B4: ='Step 3 - Zone TDH'!A32 -> 6.7420563 | C4: GPM, Minimum Required During Flushing Cycle
A5: 3 | B5: ='Step 3 - Zone TDH'!A31*2.31 -> 86.522691 | C5: Feet, Minimum Pressure During Dispersal Cycle at Pump Discharge
A6: 4 | B6: ='Step 3 - Zone TDH'!A33*2.31 -> 146.66891 | C6: Feet, Minimum Pressure During Flushing Cycle at Pump Discharge
B8: Little Giant | C8: Blaster | D8: Ashland CPM | E8: Zoeller
B9: 20XC1-05P4 | C9: 20EB05 | D9: 20+ 1/2hp | E9: 5030 7S-1/2hp | F9: 5031 5S-1/2hp | G9: 5031 9S-1hp | H9: 5032 4S-1/2hp | I9: 5032 7S-1hp
A10: 3 | B10: =LOOKUP($B$3,$A$23:$A$57,B23:B57) -> 163.2 | C10: =LOOKUP($B$3,$A$23:$A$57,C23:C57) -> 154.4 | D10: =LOOKUP($B$3,$A$23:$A$57,D23:D57) -> 164 | E10: =LOOKUP($B$3,$A$23:$A$57,E23:E57) -> 235 | F10: =LOOKUP($B$3,$A$23:$A$57,F23:F57) -> 154 | G10: =LOOKUP($B$3,$A$23:$A$57,G23:G57) -> 269 | H10: =LOOKUP($B$3,$A$23:$A$57,H23:H57) -> 119.6 | I10: =LOOKUP($B$3,$A$23:$A$57,I23:I57) -> 220.8
A11: 4 | B11: =LOOKUP($B$4,$A$23:$A$57,B23:B57) -> 157.4 | C11: =LOOKUP($B$4,$A$23:$A$57,C23:C57) -> 150.6 | D11: =LOOKUP($B$4,$A$23:$A$57,D23:D57) -> 157.4 | E11: =LOOKUP($B$4,$A$23:$A$57,E23:E57) -> 220 | F11: =LOOKUP($B$4,$A$23:$A$57,F23:F57) -> 148 | G11: =LOOKUP($B$4,$A$23:$A$57,G23:G57) -> 261 | H11: =LOOKUP($B$4,$A$23:$A$57,H23:H57) -> 116.8 | I11: =LOOKUP($B$4,$A$23:$A$57,I23:I57) -> 219.2
B13: =IF(B10>$B$5,B10,"NO") -> 163.2 | C13: =IF(C10>$B$5,C10,"NO") -> 154.4 | D13: =IF(D10>$B$5,D10,"NO") -> 164 | E13: =IF(E10>$B$5,E10,"NO") -> 235 | F13: =IF(F10>$B$5,F10,"NO") -> 154 | G13: =IF(G10>$B$5,G10,"NO") -> 269 | H13: =IF(H10>$B$5,H10,"NO") -> 119.6 | I13: =IF(I10>$B$5,I10,"NO") -> 220.8
B14: =IF(B11>$B$6,B11,"NO") -> 157.4 | C14: =IF(C11>$B$6,C11,"NO") -> 150.6 | D14: =IF(D11>$B$6,D11,"NO") -> 157.4 | E14: =IF(E11>$B$6,E11,"NO") -> 220 | F14: =IF(F11>$B$6,F11,"NO") -> 148 | G14: =IF(G11>$B$6,G11,"NO") -> 261 | H14: =IF(H11>$B$6,H11,"NO") -> NO | I14: =IF(I11>$B$6,I11,"NO") -> 219.2
B20: Little Giant | C20: Blaster | D20: Ashland CPM | E20: Zoeller
A21: Flow | B21: 20XC1-05P4 | C21: 20EB05 | D21: 20+ 1/2hp | E21: 5030 7S-1/2hp | F21: 5031 5S-1/2hp | G21: 5031 9S-1hp | H21: 5032 4S-1/2hp | I21: 5032 7S-1hp
A22: GPM | B22: Head - Feet
A23: 0 | B23: 168 | C23: 158 | D23: 170 | E23: 245 | F23: 160 | G23: 275 | H23: 122 | I23: 222
A24: 1 | B24: 166.4 | C24: 156.8 | D24: =D23-2 -> 168 | E24: =E23-2.5 -> 242.5 | F24: =F23-2 -> 158 | G24: =G23-2 -> 273 | H24: =H23-0.8 -> 121.2 | I24: =I23-0.4 -> 221.6
A25: 2 | B25: 164.8 | C25: 155.6 | D25: =D24-2 -> 166 | E25: 240 | F25: =F24-2 -> 156 | G25: =G24-2 -> 271 | H25: =H24-0.8 -> 120.4 | I25: =I24-0.4 -> 221.2
A26: 3 | B26: 163.2 | C26: 154.4 | D26: =D25-2 -> 164 | E26: =E25-5 -> 235 | F26: =F25-2 -> 154 | G26: =G25-2 -> 269 | H26: =H25-0.8 -> 119.6 | I26: =I25-0.4 -> 220.8
A27: 4 | B27: 161.6 | C27: 153.2 | D27: =D26-2 -> 162 | E27: 230 | F27: =F26-2 -> 152 | G27: =G26-2 -> 267 | H27: =H26-0.8 -> 118.8 | I27: =I26-0.4 -> 220.4
A28: 5 | B28: 160 | C28: 152 | D28: 160 | E28: =E27-5 -> 225 | F28: 150 | G28: 265 | H28: 118 | I28: 220
A29: 6 | B29: 157.4 | C29: 150.6 | D29: =D28-2.6 -> 157.4 | E29: 220 | F29: =F28-2 -> 148 | G29: =G28-4 -> 261 | H29: =H28-1.2 -> 116.8 | I29: =I28-0.8 -> 219.2
A30: 7 | B30: 154.8 | C30: 149.2 | D30: =D29-2.6 -> 154.8 | E30: =E29-17.5 -> 202.5 | F30: =F29-2 -> 146 | G30: =G29-4 -> 257 | H30: =H29-1.2 -> 115.6 | I30: =I29-0.8 -> 218.4
A31: 8 | B31: 152.2 | C31: 147.8 | D31: =D30-2.6 -> 152.2 | E31: 185 | F31: =F30-2 -> 144 | G31: =G30-4 -> 253 | H31: =H30-1.2 -> 114.4 | I31: =I30-0.8 -> 217.6
A32: 9 | B32: 149.6 | C32: 146.4 | D32: =D31-2.6 -> 149.6 | E32: =E31-17.5 -> 167.5 | F32: =F31-2 -> 142 | G32: =G31-4 -> 249 | H32: =H31-1.2 -> 113.2 | I32: =I31-0.8 -> 216.8
A33: 10 | B33: 147 | C33: 145 | D33: 147 | E33: 150 | F33: 140 | G33: 245 | H33: 112 | I33: 218
A34: 11 | B34: 143 | C34: 143 | D34: =D33-4 -> 143 | E34: =E33-30 -> 120 | F34: =F33-4 -> 136 | G34: =G33-6 -> 239 | H34: =H33-2 -> 110 | I34: =I33-1.6 -> 216.4
A35: 12 | B35: 139 | C35: 141 | D35: =D34-4 -> 139 | E35: 90 | F35: =F34-4 -> 132 | G35: =G34-6 -> 233 | H35: =H34-2 -> 108 | I35: =I34-1.6 -> 214.8
A36: 13 | B36: 135 | C36: 139 | D36: =D35-4 -> 135 | E36: =E35-20 -> 70 | F36: =F35-4 -> 128 | G36: =G35-6 -> 227 | H36: =H35-2 -> 106 | I36: =I35-1.6 -> 213.2
A37: 14 | B37: 131 | C37: 137 | D37: =D36-4 -> 131 | E37: 50 | F37: =F36-4 -> 124 | G37: =G36-6 -> 221 | H37: =H36-2 -> 104 | I37: =I36-1.6 -> 211.6
A38: 15 | B38: 127 | C38: 135 | D38: 127 | E38: 30 | F38: 120 | G38: 215 | H38: 102 | I38: 210
A39: 16 | B39: 121.6 | C39: 129 | D39: =D38-5.4 -> 121.6 | E39: 0 | F39: =F38-7 -> 113 | G39: =G38-11 -> 204 | H39: =H38-2.8 -> 99.2 | I39: =I38-5.6 -> 204.4
A40: 17 | B40: 116.2 | C40: 123 | D40: =D39-5.4 -> 116.2 | E40: 0 | F40: =F39-7 -> 106 | G40: =G39-11 -> 193 | H40: =H39-2.8 -> 96.4 | I40: =I39-5.6 -> 198.8
A41: 18 | B41: 110.8 | C41: 117 | D41: =D40-5.4 -> 110.8 | E41: 0 | F41: =F40-7 -> 99 | G41: =G40-11 -> 182 | H41: =H40-2.8 -> 93.6 | I41: =I40-5.6 -> 193.2
A42: 19 | B42: 105.4 | C42: 111 | D42: =D41-5.4 -> 105.4 | E42: 0 | F42: =F41-7 -> 92 | G42: =G41-11 -> 171 | H42: =H41-2.8 -> 90.8 | I42: =I41-5.6 -> 187.6
A43: 20 | B43: 100 | C43: 105 | D43: 100 | E43: 0 | F43: 85 | G43: 160 | H43: 88 | I43: 182
A44: 21 | B44: 93.4 | C44: 99.6 | D44: =D43-6 -> 94 | E44: 0 | F44: =F43-10 -> 75 | G44: =G43-20 -> 140 | H44: =H43-4.6 -> 83.4 | I44: =I43-6.8 -> 175.2
A45: 22 | B45: 86.8 | C45: 94.2 | D45: =D44-6 -> 88 | E45: 0 | F45: =F44-10 -> 65 | G45: =G44-20 -> 120 | H45: =H44-4.6 -> 78.8 | I45: =I44-6.8 -> 168.4
A46: 23 | B46: 80.2 | C46: 88.8 | D46: =D45-6 -> 82 | E46: 0 | F46: =F45-10 -> 55 | G46: =G45-20 -> 100 | H46: =H45-4.6 -> 74.2 | I46: =I45-6.8 -> 161.6
A47: 24 | B47: 73.6 | C47: 83.4 | D47: =D46-6 -> 76 | E47: 0 | F47: =F46-10 -> 45 | G47: =G46-20 -> 80 | H47: =H46-4.6 -> 69.6 | I47: =I46-6.8 -> 154.8
A48: 25 | B48: 67 | C48: 78 | D48: 70 | E48: 0 | F48: 35 | G48: 60 | H48: 65 | I48: 148
A49: 26 | B49: 58.4 | C49: 76.4 | D49: =D48-8 -> 62 | E49: 0 | F49: =F48-5 -> 30 | G49: =G48-7.5 -> 52.5 | H49: =H48-5 -> 60 | I49: =I48-8.6 -> 139.4
...

Sheet Pipe Data .5" to 24"
A1: Friction Loss Characteristics, PVC IPS Pipe
A4: Single Section/Same Flow
A5: 150 | B5: = C | E5: =#REF! -> #REF! | F5: GPM Supply Main Dosing
A6: 100 | B6: = Q (GPM) | E6: =#REF! -> #REF! | F6: GPM Supply Main Flushing
A7: 100 | B7: = Total Line length, feet | E7: =E6-E5 -> #REF! | F7: GPM Return Main Flushing
A10: Size | B10: 1/2" | D10: 3/4" | F10: 1" | H10: 1 1/4" | J10: 1 1/2" | L10: 2" | N10: 2 1/2" | P10: 3" | R10: 4" | T10: 5"
A11: OD | B11: 0.84 | D11: 1.05 | F11: 1.315 | H11: 1.66 | J11: 1.9 | L11: 2.375 | N11: 2.875 | P11: 3.5 | R11: 4.5 | T11: 5.563
A12: ID | B12: 0.622 | D12: 0.824 | F12: 1.049 | H12: 1.38 | J12: 1.61 | L12: 2.067 | N12: 2.469 | P12: 3.068 | R12: 4.026 | T12: 5.407
A13: Wall Thk | B13: 0.109 | D13: 0.113 | F13: 0.133 | H13: 0.14 | J13: 0.145 | L13: 0.154 | N13: 0.203 | P13: 0.216 | R13: 0.237 | T13: =T11-T12 -> 0.156
B14: Velocity FPS | C14: PSI Loss | D14: Velocity FPS | E14: PSI Loss | F14: Velocity FPS | G14: PSI Loss | H14: Velocity FPS | I14: PSI Loss | J14: Velocity FPS | K14: PSI Loss | L14: Velocity FPS | M14: PSI Loss | N14: Velocity FPS | O14: PSI Loss | P14: Velocity FPS | Q14: PSI Loss | R14: Velocity FPS | S14: PSI Loss | T14: Velocity FPS | U14: PSI Loss
A15: Total | B15: =0.4085*A6/B12^2 -> 105.5872 | C15: =0.2083*(100/A5)^1.852*A6^1.852/B12^4.866*0.433*A7/100 -> 2170.062 | D15: =0.4085*A6/D12^2 -> 60.16413 | E15: =0.2083*(100/A5)^1.852*A6^1.852/D12^4.866*0.433*A7/100 -> 552.27368 | F15: =0.4085*A6/F12^2 -> 37.122831 | G15: =0.2083*(100/A5)^1.852*A6^1.852/F12^4.866*0.433*A7/100 -> 170.59356 | H15: =0.4085*A6/H12^2 -> 21.450326 | I15: =0.2083*(100/A5)^1.852*A6^1.852/H12^4.866*0.433*A7/100 -> 44.916356 | J15: =0.4085*A6/J12^2 -> 15.759423 | K15: =0.2083*(100/A5)^1.852*A6^1.852/J12^4.866*0.433*A7/100 -> 21.214922 | L15: =0.4085*A6/L12^2 -> 9.5611715 | M15: =0.2083*(100/A5)^1.852*A6^1.852/L12^4.866*0.433*A7/100 -> 6.2894026 | N15: =0.4085*A6/N12^2 -> 6.7011584 | O15: =0.2083*(100/A5)^1.852*A6^1.852/N12^4.866*0.433*A7/100 -> 2.6487961 | P15: =0.4085*A6/P12^2 -> 4.3399163 | Q15: =0.2083*(100/A5)^1.852*A6^1.852/P12^4.866*0.433*A7/100 -> 0.92048771 | R15: =0.4085*A6/R12^2 -> 2.5202552 | S15: =0.2083*(100/A5)^1.852*A6^1.852/R12^4.866*0.433*A7/100 -> 0.2453242 | T15: =0.4085*A6/T12^2 -> 1.3972667 | U15: =0.2083*(100/A5)^1.852*A6^1.852/T12^4.866*0.433*A7/100 -> 0.058410438
A16: % Loss | C16: =C15/A7/0.433*100 -> 5011.6905 | E16: =E15/A7/0.433*100 -> 1275.4588 | G16: =G15/A7/0.433*100 -> 393.98051 | I16: =I15/A7/0.433*100 -> 103.73292 | K16: =K15/A7/0.433*100 -> 48.995201 | M16: =M15/A7/0.433*100 -> 14.525179 | O16: =O15/A7/0.433*100 -> 6.117312 | Q16: =Q15/A7/0.433*100 -> 2.1258377 | S16: =S15/A7/0.433*100 -> 0.56656859 | U16: =U15/A7/0.433*100 -> 0.13489708
A18: Gallons Per Section | B18: =$A$7*B12^2*0.04079905 -> 1.57845 | D18: =$A$7*D12^2*0.04079905 -> 2.7701576 | F18: =$A$7*F12^2*0.04079905 -> 4.4895315 | H18: =$A$7*H12^2*0.04079905 -> 7.7697711 | J18: =$A$7*J12^2*0.04079905 -> 10.575522 | L18: =$A$7*L12^2*0.04079905 -> 17.431349 | N18: =$A$7*N12^2*0.04079905 -> 24.870942 | P18: =$A$7*P12^2*0.04079905 -> 38.402612 | R18: =$A$7*R12^2*0.04079905 -> 66.129858 | T18: =$A$7*T12^2*0.04079905 -> 119.27867
A21: Size | B21: 6" | D21: 8" | F21: 10" | H21: 12" | J21: 14" | L21: *15" | N21: 16" | P21: 18" | R21: 20" | T21: 24"
A22: OD | B22: 6.625 | D22: 8.625 | F22: 10.75 | H22: 12.75 | J22: 14 | L22: 15.3 | N22: 16 | P22: 18 | R22: 20 | T22: 24
A23: ID | B23: 6.065 | D23: 7.981 | F23: 10.02 | H23: 11.938 | J23: 13.124 | L23: 14.82 | N23: 15 | P23: 16.876 | R23: 18.814 | T23: 22.226
A24: Wall Thk | B24: =B22-B23 -> 0.56 | D24: =D22-D23 -> 0.644 | F24: =F22-F23 -> 0.73 | H24: =H22-H23 -> 0.812 | J24: =J22-J23 -> 0.876 | L24: =L22-L23 -> 0.48 | N24: =N22-N23 -> 1 | P24: =P22-P23 -> 1.124 | R24: =R22-R23 -> 1.186 | T24: =T22-T23 -> 1.774
B25: Velocity FPS | C25: PSI Loss | D25: Velocity FPS | E25: PSI Loss | F25: Velocity FPS | G25: PSI Loss | H25: Velocity FPS | I25: PSI Loss | J25: Velocity FPS | K25: PSI Loss | L25: Velocity FPS | M25: PSI Loss | N25: Velocity FPS | O25: PSI Loss | P25: Velocity FPS | Q25: PSI Loss | R25: Velocity FPS | S25: PSI Loss | T25: Velocity FPS | U25: PSI Loss
A26: Total | B26: =0.4085*A6/B23^2 -> 1.1105304 | C26: =0.2083*(100/A5)^1.852*A6^1.852/B23^4.866*0.433*A7/100 -> 0.033404229 | D26: =0.4085*A6/D23^2 -> 0.64132392 | E26: =0.2083*(100/A5)^1.852*A6^1.852/D23^4.866*0.433*A7/100 -> 0.0087830485 | F26: =0.4085*A6/F23^2 -> 0.40687089 | G26: =0.2083*(100/A5)^1.852*A6^1.852/F23^4.866*0.433*A7/100 -> 0.0029029117 | H26: =0.4085*A6/H23^2 -> 0.2866348 | I26: =0.2083*(100/A5)^1.852*A6^1.852/H23^4.866*0.433*A7/100 -> 0.0012379614 | J26: =0.4085*A6/J23^2 -> 0.23716993 | K26: =0.2083*(100/A5)^1.852*A6^1.852/J23^4.866*0.433*A7/100 -> 0.00078081099 | L26: =0.4085*A6/L23^2 -> 0.18599259 | M26: =0.2083*(100/A5)^1.852*A6^1.852/L23^4.866*0.433*A7/100 -> 0.00043222392 | N26: =0.4085*A6/N23^2 -> 0.18155556 | O26: =0.2083*(100/A5)^1.852*A6^1.852/N23^4.866*0.433*A7/100 -> 0.00040756426 | P26: =0.4085*A6/P23^2 -> 0.1434343 | Q26: =0.2083*(100/A5)^1.852*A6^1.852/P23^4.866*0.433*A7/100 -> 0.00022970089 | R26: =0.4085*A6/R23^2 -> 0.11540637 | S26: =0.2083*(100/A5)^1.852*A6^1.852/R23^4.866*0.433*A7/100 -> 0.00013534148 | T26: =0.4085*A6/T23^2 -> 0.082693132 | U26: =0.2083*(100/A5)^1.852*A6^1.852/T23^4.866*0.433*A7/100 -> 6.0149084e-05
A27: % Loss | C27: =C26/A7/0.433*100 -> 0.077146026 | E27: =E26/A7/0.433*100 -> 0.020284177 | G27: =G26/A7/0.433*100 -> 0.006704184 | I27: =I26/A7/0.433*100 -> 0.0028590333 | K27: =K26/A7/0.433*100 -> 0.0018032586 | M27: =M26/A7/0.433*100 -> 0.00099820766 | O27: =O26/A7/0.433*100 -> 0.00094125694 | Q27: =Q26/A7/0.433*100 -> 0.00053048705 | S27: =S26/A7/0.433*100 -> 0.00031256693 | U27: =U26/A7/0.433*100 -> 0.00013891243
A29: Gallons Per Section | B29: =$A$7*B23^2*0.04079905 -> 150.07614 | D29: =$A$7*D23^2*0.04079905 -> 259.8751 | F29: =$A$7*F23^2*0.04079905 -> 409.62409 | H29: =$A$7*H23^2*0.04079905 -> 581.4511 | J29: =$A$7*J23^2*0.04079905 -> 702.72029 | L29: =$A$7*L23^2*0.04079905 -> 896.07933 | N29: =$A$7*N23^2*0.04079905 -> 917.97863 | P29: =$A$7*P23^2*0.04079905 -> 1161.9544 | R29: =$A$7*R23^2*0.04079905 -> 1444.1501 | T29: =$A$7*T23^2*0.04079905 -> 2015.453
A32: Q = | B32: (Vxd^2) ÷ .4085
A33: Gal/1' = | B33: .04079905 x d^2
A34: Gal/100' = | B34: r^2 x 16.32
A42: Q = | B42: Volume in gallons per minute
A43: V = | B43: Velocity in feet per second
A44: Gal = | B44: US gallons
A45: d = | B45: Inside diameter in inches
A46: r = | B46: Inside radius in inches
A47: .4085 = | B47: Unit conversion factor
A48: 0.04079905 = | B48: Unit conversion factor
A49: 16.32 = | B49: Unit conversion factor

Sheet Drip Tube Data
B3: Drip Tube Model # | C3: Tube ID Inches | D3: Emitter Kd | E3: Emitter Exponent | F3: Emitter Spacing Inches | G3: Emitter Spacing Feet | H3: Nominal Emitter Flow GPH | I3: Actual Flow @ 30 psi | J3: Nominal Flow GPM
B4: G-WFPC-16-2-12-PRO | C4: 0.55 | D4: 2.07 | E4: 0.05 | F4: 12 | G4: 1 | H4: 0.6 | I4: 0.6 | J4: =Table24[[#This Row],[Actual Flow @ 30 psi]]/60 -> 0.01
B5: G-WFPC-16-2-24-PRO | C5: 0.55 | D5: 2.07 | E5: 0.05 | F5: 24 | G5: 2 | H5: 0.6 | I5: 0.6 | J5: =Table24[[#This Row],[Actual Flow @ 30 psi]]/60 -> 0.01
B6: G-WFPC-16-4-12-PRO | C6: 0.55 | D6: 2.07 | E6: 0.02 | F6: 12 | G6: 1 | H6: 0.9 | I6: 0.9 | J6: =Table24[[#This Row],[Actual Flow @ 30 psi]]/60 -> 0.015
B7: G-WFPC-16-4-24-PRO | C7: 0.55 | D7: 2.07 | E7: 0.02 | F7: 24 | G7: 2 | H7: 0.9 | I7: 0.9 | J7: =Table24[[#This Row],[Actual Flow @ 30 psi]]/60 -> 0.015
B8: G-WFPC-17-1.6-12-ECO | C8: 0.56 | D8: 0.92 | E8: 0 | F8: 12 | G8: 1 | H8: 0.42 | I8: 0.42 | J8: =Table24[[#This Row],[Actual Flow @ 30 psi]]/60 -> 0.007
B9: G-WFPC-17-1.6-24-ECO | C9: 0.56 | D9: 0.92 | E9: 0 | F9: 24 | G9: 2 | H9: 0.42 | I9: 0.42 | J9: =Table24[[#This Row],[Actual Flow @ 30 psi]]/60 -> 0.007
B10: G-WFPC-17-2-12-ECO | C10: 0.56 | D10: 0.92 | E10: 0 | F10: 12 | G10: 1 | H10: 0.55 | I10: 0.6 | J10: =Table24[[#This Row],[Actual Flow @ 30 psi]]/60 -> 0.01
B11: G-WFPC-17-2-24-ECO | C11: 0.56 | D11: 0.92 | E11: 0 | F11: 24 | G11: 2 | H11: 0.55 | I11: 0.6 | J11: =Table24[[#This Row],[Actual Flow @ 30 psi]]/60 -> 0.01
B12: G-WFPC-17-4-12-ECO | C12: 0.56 | D12: 0.92 | E12: 0 | F12: 12 | G12: 1 | H12: 1 | I12: 1 | J12: =Table24[[#This Row],[Actual Flow @ 30 psi]]/60 -> 0.016666667
B13: G-WFPC-17-4-24-ECO | C13: 0.56 | D13: 0.92 | E13: 0 | F13: 24 | G13: 2 | H13: 1 | I13: 1 | J13: =Table24[[#This Row],[Actual Flow @ 30 psi]]/60 -> 0.016666667
B16: Inlet Pressure Psi | C16: Distal End Pressure | D16: Flush Velocity FPS | E16: Drip Tube Spacing Ft
B17: 60 | C17: 50 | D17: 3 | E17: 1
B18: 50 | C18: 40 | D18: 2.5 | E18: 1.5
B19: 40 | C19: 30 | D19: 2 | E19: 2
B20: 30 | C20: 20 | D20: 1.5 | E20: 2.5
B21: 20 | C21: 10 | D21: 1 | E21: 3
B22: 10 | C22: 7 | D22: 0.5 | E22: 3.5
E23: 4
C28: gpm | D28: spacing | E28: flush velocity | F28: lat flush Q | G28: Drip Tube Q/1'
B29: ='Step 3 - Zone TDH'!A3 -> G-WFPC-16-4-12-PRO | C29: =LOOKUP(B29,Table24[Drip Tube Model '#],Table24[Nominal Flow GPM]) -> 0.015 | D29: =LOOKUP(B29,Table24[Drip Tube Model '#],Table24[Emitter Spacing Feet]) -> 1 | E29: ='Step 3 - Zone TDH'!A6 -> 2 | F29: =E29/(0.4085/(LOOKUP(B29,Table24[Drip Tube Model '#],Table24[Tube ID Inches]))^2) -> 1.4810282 | G29: =LOOKUP(B29,Table24[Drip Tube Model '#],Table24[Tube ID Inches])^2*0.04079905 -> 0.012341713
B30: Linear Feet Per Zone | C30: ='Step 3 - Zone TDH'!A11 -> 252 | G30: =C30*G29 -> 3.1101116
B31: Number of Laterals | C31: ='Step 3 - Zone TDH'!A10 -> 2
B32: Q/Lateral Disposal | C32: =C30*C29/D29/C31 -> 1.89
B33: Q Zone Disposal | C33: =C30*C29/D29 -> 3.78
B34: Q/Lateral Flushing | C34: =C32+F29 -> 3.3710282
B35: Q Zone Flushing | C35: =C33+(C31*F29) -> 6.7420563
B36: Q Return | C36: =C35-C33 -> 2.9620563

Sheet Drip Tube Loss Calculator
A1: Geoflow PC
A2: 1222Met-V1
B3: INPUT
B4: Drip Tube, Emitter & Spacing | C4: ='Step 3 - Zone TDH'!A3 -> G-WFPC-16-4-12-PRO
B5: Drip Tube I.D. | C5: =LOOKUP(C4,Table24[Drip Tube Model '#],Table24[Tube ID Inches]) -> 0.55
B6: Hazen-Williams C - poly | C6: 140
B7: H-W Constant | C7: =10.472/($C$6^1.852) -> 0.0011101982
B9: Land Slope % (+ dn) | C9: 0
B10: Downstream Dosing pressure PSI | C10: 20
B11: Kd factor | C11: =LOOKUP(C4,Table24[Drip Tube Model '#],Table24[Emitter Kd]) -> 2.07
B12: Flushing Velocity FPS | C12: ='Step 3 - Zone TDH'!A6 -> 2
B13: Distal End Pressure PSI | C13: ='Step 3 - Zone TDH'!A8 -> 20
B14: Emitter Flow Rate at 30 psi GPH | C14: =LOOKUP(C4,Table24[Drip Tube Model '#],Table24[Actual Flow @ 30 psi]) -> 0.9
B15: Inlet Pressure PSI | C15: ='Step 3 - Zone TDH'!A7 -> 20
B16: Emitter Spacing Inches | C16: =LOOKUP(C4,Table24[Drip Tube Model '#],Table24[Emitter Spacing Inches]) -> 12
B17: Emitter Coeff (Cd) | C17: =C14/C15^C18 -> 0.84766043
B18: Emitter Exp (X) | C18: =LOOKUP(C4,Table24[Drip Tube Model '#],Table24[Emitter Exponent]) -> 0.02
B19: Actual Flow | C19: =$C$17*$C$10^$C$18 -> 0.9
B22: Disposal | O22: Flushing
A23: Section | B23: Downstream | C23: Downstream | D23: Downstream | E23: Upstream | F23: Upstream | G23: Upstream | H23: Upstream | I23: Upstream | J23: EU% | K23: Cumulative | L23: Barb loss Ft | M23: Barb loss Psi | N23: Travel time | O23: Section | P23: Downstream | Q23: Downstream | R23: Downstream | S23: Upstream | T23: Upstream | U23: Upstream | V23: Upstream | W23: Upstream | Y23: Cumulative | Z23: Barb loss Ft | AA23: Barb loss in psi | AB23: Travel time
A24: Length | B24: Press | C24: Flow | D24: Emitter Flow | E24: Flow | F24: Friction Loss | G24: Elevation Gain | H24: Pressure | I24: Pressure | K24: Head Loss | N24: length/velocity | O24: Length | P24: Press | Q24: Flow | R24: Emitter Flow | S24: Flow | T24: Friction Loss | U24: Elevation Gain | V24: Pressure | W24: Pressure | Y24: Head Loss
A25: Feet | B25: PSI | C25: GPM | D25: GPH | E25: GPM | F25: Feet | G25: Feet | H25: Feet | I25: PSI | K25: PSI | O25: Feet | P25: PSI | Q25: GPM | R25: GPH | S25: GPM | T25: Feet | U25: Feet | V25: Feet | W25: PSI | Y25: PSI
A26: 0 | B26: =C10 -> 20 | C26: 0 | D26: =$C$17*B26^$C$18 -> 0.9 | E26: =C26+D26/60 -> 0.015 | F26: =(($C$7*($C$16/12)*(E26)^1.852)/($C$5^4.871)+L26)-G26 -> 2.1743549e-05 | G26: =$C$9*($C$16/12)/100 -> 0 | H26: =(B26*2.31)+F26-G26 -> 46.200022 | I26: =H26/2.31 -> 20.000009 | J26: =(1-1.27*0.05)*($D$26/((E26*60)/((A26/($C$16/12)+1)))) -> 0.9365 | K26: =F26*0.433 -> 9.4149567e-06 | L26: =($C$11*((0.4085*E26/$C$5^2))^2)/64.4 -> 1.3188651e-05 | M26: =L26/2.31 -> 5.7093725e-06 | N26: 0 | O26: 0 | P26: =C13 -> 20 | Q26: =(($C$5^2*$C$12)/0.4085) -> 1.4810282 | R26: =$C$17*P26^$C$18 -> 0.9 | S26: =Q26+R26/60 -> 1.4960282 | T26: =(($C$7*($C$16/12)*(S26)^1.852)/($C$5^4.871)+Z26)-U26 -> 0.17424981 | U26: =$C$9*($C$16/12)/100 -> 0 | V26: =(P26*2.31)+T26-U26 -> 46.37425 | W26: =V26/2.31 -> 20.075433 | Y26: =T26*0.433 -> 0.075450166 | Z26: =($C$11*((0.4085*S26/$C$5^2))^2)/64.4 -> 0.13118899 | AA26: =Z26/2.31 -> 0.056791769 | AB26: 0
A27: =A26+$C$16/12 -> 1 | B27: =I26 -> 20.000009 | C27: =E26 -> 0.015 | D27: =$C$17*I26^$C$18 -> 0.90000001 | E27: =C27+D27/60 -> 0.03 | F27: =(($C$7*($C$16/12)*(E27)^1.852)/($C$5^4.871)+L27)-G27 -> 8.3637811e-05 | G27: =$C$9*($C$16/12)/100 -> 0 | H27: =(B27*2.31)+F27-G27 -> 46.200105 | I27: =H27/2.31 -> 20.000046 | J27: =(1-1.27*0.05)*($D$26/((E27*60)/((A27/($C$16/12)+1)))) -> 0.9365 | K27: =K26+(F27*0.433) -> 4.5630129e-05 | L27: =($C$11*((0.4085*E27/$C$5^2))^2)/64.4 -> 5.2754603e-05 | M27: =(L27/2.31)+M26 -> 2.8546863e-05 | N27: =($C$16/12)/(0.4085*E26/$C$5^2) -> 49.367605 | O27: =O26+$C$16/12 -> 1 | P27: =W26 -> 20.075433 | Q27: =S26 -> 1.4960282 | R27: =$C$17*W26^$C$18 -> 0.90006776 | S27: =Q27+R27/60 -> 1.5110293 | T27: =(($C$7*($C$16/12)*(S27)^1.852)/($C$5^4.871)+Z27)-U27 -> 0.17769702 | U27: =$C$9*($C$16/12)/100 -> 0 | V27: =(P27*2.31)+T27-U27 -> 46.551947 | W27: =V27/2.31 -> 20.152358 | Y27: =Y26+(T27*0.433) -> 0.15239297 | Z27: =($C$11*((0.4085*S27/$C$5^2))^2)/64.4 -> 0.13383312 | AA27: =(Z27/2.31)+AA26 -> 0.11472818 | AB27: =($C$16/12)/(0.4085*S26/$C$5^2) -> 0.49498673
A28: =A27+$C$16/12 -> 2 | B28: =I27 -> 20.000046 | C28: =E27 -> 0.03 | D28: =$C$17*I27^$C$18 -> 0.90000004 | E28: =C28+D28/60 -> 0.045000001 | F28: =(($C$7*($C$16/12)*(E28)^1.852)/($C$5^4.871)+L28)-G28 -> 0.00018413788 | G28: =$C$9*($C$16/12)/100 -> 0 | H28: =(B28*2.31)+F28-G28 -> 46.20029 | I28: =H28/2.31 -> 20.000125 | J28: =(1-1.27*0.05)*($D$26/((E28*60)/((A28/($C$16/12)+1)))) -> 0.93649998 | K28: =K27+(F28*0.433) -> 0.00012536183 | L28: =($C$11*((0.4085*E28/$C$5^2))^2)/64.4 -> 0.00011869786 | M28: =(L28/2.31)+M27 -> 7.9931217e-05 | N28: =($C$16/12)/(0.4085*E27/$C$5^2)+N27 -> 74.051407 | O28: =O27+$C$16/12 -> 2 | P28: =W27 -> 20.152358 | Q28: =S27 -> 1.5110293 | R28: =$C$17*W27^$C$18 -> 0.90013661 | S28: =Q28+R28/60 -> 1.5260316 | T28: =(($C$7*($C$16/12)*(S28)^1.852)/($C$5^4.871)+Z28)-U28 -> 0.1811777 | U28: =$C$9*($C$16/12)/100 -> 0 | V28: =(P28*2.31)+T28-U28 -> 46.733125 | W28: =V28/2.31 -> 20.23079 | Y28: =Y27+(T28*0.433) -> 0.23084292 | Z28: =($C$11*((0.4085*S28/$C$5^2))^2)/64.4 -> 0.13650384 | AA28: =(Z28/2.31)+AA27 -> 0.17382076 | AB28: =($C$16/12)/(0.4085*S27/$C$5^2)+AB27 -> 0.98505934
A29: =A28+$C$16/12 -> 3 | B29: =I28 -> 20.000125 | C29: =E28 -> 0.045000001 | D29: =$C$17*I28^$C$18 -> 0.90000011 | E29: =C29+D29/60 -> 0.060000003 | F29: =(($C$7*($C$16/12)*(E29)^1.852)/($C$5^4.871)+L29)-G29 -> 0.00032250691 | G29: =$C$9*($C$16/12)/100 -> 0 | H29: =(B29*2.31)+F29-G29 -> 46.200612 | I29: =H29/2.31 -> 20.000265 | J29: =(1-1.27*0.05)*($D$26/((E29*60)/((A29/($C$16/12)+1)))) -> 0.93649996 | K29: =K28+(F29*0.433) -> 0.00026500732 | L29: =($C$11*((0.4085*E29/$C$5^2))^2)/64.4 -> 0.00021101843 | M29: =(L29/2.31)+M28 -> 0.00017128119 | N29: =($C$16/12)/(0.4085*E28/$C$5^2)+N28 -> 90.507276 | O29: =O28+$C$16/12 -> 3 | P29: =W28 -> 20.23079 | Q29: =S28 -> 1.5260316 | R29: =$C$17*W28^$C$18 -> 0.90020655 | S29: =Q29+R29/60 -> 1.541035 | T29: =(($C$7*($C$16/12)*(S29)^1.852)/($C$5^4.871)+Z29)-U29 -> 0.18469186 | U29: =$C$9*($C$16/12)/100 -> 0 | V29: =(P29*2.31)+T29-U29 -> 46.917816 | W29: =V29/2.31 -> 20.310743 | Y29: =Y28+(T29*0.433) -> 0.31081449 | Z29: =($C$11*((0.4085*S29/$C$5^2))^2)/64.4 -> 0.13920116 | AA29: =(Z29/2.31)+AA28 -> 0.234081 | AB29: =($C$16/12)/(0.4085*S28/$C$5^2)+AB28 -> 1.4703141
A30: =A29+$C$16/12 -> 4 | B30: =I29 -> 20.000265 | C30: =E29 -> 0.060000003 | D30: =$C$17*I29^$C$18 -> 0.90000024 | E30: =C30+D30/60 -> 0.075000007 | F30: =(($C$7*($C$16/12)*(E30)^1.852)/($C$5^4.871)+L30)-G30 -> 0.00049825803 | G30: =$C$9*($C$16/12)/100 -> 0 | H30: =(B30*2.31)+F30-G30 -> 46.20111 | I30: =H30/2.31 -> 20.000481 | J30: =(1-1.27*0.05)*($D$26/((E30*60)/((A30/($C$16/12)+1)))) -> 0.93649992 | K30: =K29+(F30*0.433) -> 0.00048075305 | L30: =($C$11*((0.4085*E30/$C$5^2))^2)/64.4 -> 0.00032971632 | M30: =(L30/2.31)+M29 -> 0.00031401552 | N30: =($C$16/12)/(0.4085*E29/$C$5^2)+N29 -> 102.84918 | O30: =O29+$C$16/12 -> 4 | P30: =W29 -> 20.310743 | Q30: =S29 -> 1.541035 | R30: =$C$17*W29^$C$18 -> 0.90027756 | S30: =Q30+R30/60 -> 1.5560396 | T30: =(($C$7*($C$16/12)*(S30)^1.852)/($C$5^4.871)+Z30)-U30 -> 0.18823949 | U30: =$C$9*($C$16/12)/100 -> 0 | V30: =(P30*2.31)+T30-U30 -> 47.106056 | W30: =V30/2.31 -> 20.392232 | Y30: =Y29+(T30*0.433) -> 0.39232219 | Z30: =($C$11*((0.4085*S30/$C$5^2))^2)/64.4 -> 0.14192508 | AA30: =(Z30/2.31)+AA29 -> 0.29552043 | AB30: =($C$16/12)/(0.4085*S29/$C$5^2)+AB29 -> 1.9508444
A31: =A30+$C$16/12 -> 5 | B31: =I30 -> 20.000481 | C31: =E30 -> 0.075000007 | D31: =$C$17*I30^$C$18 -> 0.90000043 | E31: =C31+D31/60 -> 0.090000014 | F31: =(($C$7*($C$16/12)*(E31)^1.852)/($C$5^4.871)+L31)-G31 -> 0.0007110303 | G31: =$C$9*($C$16/12)/100 -> 0 | H31: =(B31*2.31)+F31-G31 -> 46.201821 | I31: =H31/2.31 -> 20.000788 | J31: =(1-1.27*0.05)*($D$26/((E31*60)/((A31/($C$16/12)+1)))) -> 0.93649986 | K31: =K30+(F31*0.433) -> 0.00078862917 | L31: =($C$11*((0.4085*E31/$C$5^2))^2)/64.4 -> 0.00047479156 | M31: =(L31/2.31)+M30 -> 0.000519553 | N31: =($C$16/12)/(0.4085*E30/$C$5^2)+N30 -> 112.7227 | O31: =O30+$C$16/12 -> 5 | P31: =W30 -> 20.392232 | Q31: =S30 -> 1.5560396 | R31: =$C$17*W30^$C$18 -> 0.90034966 | S31: =Q31+R31/60 -> 1.5710455 | T31: =(($C$7*($C$16/12)*(S31)^1.852)/($C$5^4.871)+Z31)-U31 -> 0.19182059 | U31: =$C$9*($C$16/12)/100 -> 0 | V31: =(P31*2.31)+T31-U31 -> 47.297876 | W31: =V31/2.31 -> 20.475271 | Y31: =Y30+(T31*0.433) -> 0.47538051 | Z31: =($C$11*((0.4085*S31/$C$5^2))^2)/64.4 -> 0.14467562 | AA31: =(Z31/2.31)+AA30 -> 0.35815056 | AB31: =($C$16/12)/(0.4085*S30/$C$5^2)+AB30 -> 2.4267411
A32: =A31+$C$16/12 -> 6 | B32: =I31 -> 20.000788 | C32: =E31 -> 0.090000014 | D32: =$C$17*I31^$C$18 -> 0.90000071 | E32: =C32+D32/60 -> 0.10500003 | F32: =(($C$7*($C$16/12)*(E32)^1.852)/($C$5^4.871)+L32)-G32 -> 0.00096053858 | G32: =$C$9*($C$16/12)/100 -> 0 | H32: =(B32*2.31)+F32-G32 -> 46.202782 | I32: =H32/2.31 -> 20.001204 | J32: =(1-1.27*0.05)*($D$26/((E32*60)/((A32/($C$16/12)+1)))) -> 0.93649977 | K32: =K31+(F32*0.433) -> 0.0012045424 | L32: =($C$11*((0.4085*E32/$C$5^2))^2)/64.4 -> 0.00064624419 | M32: =(L32/2.31)+M31 -> 0.00079931239 | N32: =($C$16/12)/(0.4085*E31/$C$5^2)+N31 -> 120.95063 | O32: =O31+$C$16/12 -> 6 | P32: =W31 -> 20.475271 | Q32: =S31 -> 1.5710455 | R32: =$C$17*W31^$C$18 -> 0.90042284 | S32: =Q32+R32/60 -> 1.5860525 | T32: =(($C$7*($C$16/12)*(S32)^1.852)/($C$5^4.871)+Z32)-U32 -> 0.19543518 | U32: =$C$9*($C$16/12)/100 -> 0 | V32: =(P32*2.31)+T32-U32 -> 47.493312 | W32: =V32/2.31 -> 20.559875 | Y32: =Y31+(T32*0.433) -> 0.56000394 | Z32: =($C$11*((0.4085*S32/$C$5^2))^2)/64.4 -> 0.14745278 | AA32: =(Z32/2.31)+AA31 -> 0.42198293 | AB32: =($C$16/12)/(0.4085*S31/$C$5^2)+AB31 -> 2.8980923
A33: =A32+$C$16/12 -> 7 | B33: =I32 -> 20.001204 | C33: =E32 -> 0.10500003 | D33: =$C$17*I32^$C$18 -> 0.90000108 | E33: =C33+D33/60 -> 0.12000004 | F33: =(($C$7*($C$16/12)*(E33)^1.852)/($C$5^4.871)+L33)-G33 -> 0.0012465482 | G33: =$C$9*($C$16/12)/100 -> 0 | H33: =(B33*2.31)+F33-G33 -> 46.204028 | I33: =H33/2.31 -> 20.001744 | J33: =(1-1.27*0.05)*($D$26/((E33*60)/((A33/($C$16/12)+1)))) -> 0.93649966 | K33: =K32+(F33*0.433) -> 0.0017442978 | L33: =($C$11*((0.4085*E33/$C$5^2))^2)/64.4 -> 0.00084407425 | M33: =(L33/2.31)+M32 -> 0.0011647125 | N33: =($C$16/12)/(0.4085*E32/$C$5^2)+N32 -> 128.00314 | O33: =O32+$C$16/12 -> 7 | P33: =W32 -> 20.559875 | Q33: =S32 -> 1.5860525 | R33: =$C$17*W32^$C$18 -> 0.9004971 | S33: =Q33+R33/60 -> 1.6010608 | T33: =(($C$7*($C$16/12)*(S33)^1.852)/($C$5^4.871)+Z33)-U33 -> 0.19908325 | U33: =$C$9*($C$16/12)/100 -> 0 | V33: =(P33*2.31)+T33-U33 -> 47.692395 | W33: =V33/2.31 -> 20.646058 | Y33: =Y32+(T33*0.433) -> 0.64620699 | Z33: =($C$11*((0.4085*S33/$C$5^2))^2)/64.4 -> 0.15025657 | AA33: =(Z33/2.31)+AA32 -> 0.48702907 | AB33: =($C$16/12)/(0.4085*S32/$C$5^2)+AB32 -> 3.3649835
A34: =A33+$C$16/12 -> 8 | B34: =I33 -> 20.001744 | C34: =E33 -> 0.12000004 | D34: =$C$17*I33^$C$18 -> 0.90000157 | E34: =C34+D34/60 -> 0.13500007 | F34: =(($C$7*($C$16/12)*(E34)^1.852)/($C$5^4.871)+L34)-G34 -> 0.0015688605 | G34: =$C$9*($C$16/12)/100 -> 0 | H34: =(B34*2.31)+F34-G34 -> 46.205597 | I34: =H34/2.31 -> 20.002423 | J34: =(1-1.27*0.05)*($D$26/((E34*60)/((A34/($C$16/12)+1)))) -> 0.93649951 | K34: =K33+(F34*0.433) -> 0.0024236144 | L34: =($C$11*((0.4085*E34/$C$5^2))^2)/64.4 -> 0.0010682818 | M34: =(L34/2.31)+M33 -> 0.0016271721 | N34: =($C$16/12)/(0.4085*E33/$C$5^2)+N33 -> 134.17409 | O34: =O33+$C$16/12 -> 8 | P34: =W33 -> 20.646058 | Q34: =S33 -> 1.6010608 | R34: =$C$17*W33^$C$18 -> 0.90057244 | S34: =Q34+R34/60 -> 1.6160703 | T34: =(($C$7*($C$16/12)*(S34)^1.852)/($C$5^4.871)+Z34)-U34 -> 0.2027648 | U34: =$C$9*($C$16/12)/100 -> 0 | V34: =(P34*2.31)+T34-U34 -> 47.89516 | W34: =V34/2.31 -> 20.733835 | Y34: =Y33+(T34*0.433) -> 0.73400415 | Z34: =($C$11*((0.4085*S34/$C$5^2))^2)/64.4 -> 0.15308701 | AA34: =(Z34/2.31)+AA33 -> 0.55330051 | AB34: =($C$16/12)/(0.4085*S33/$C$5^2)+AB33 -> 3.8274982
A35: =A34+$C$16/12 -> 9 | B35: =I34 -> 20.002423 | C35: =E34 -> 0.13500007 | D35: =$C$17*I34^$C$18 -> 0.90000218 | E35: =C35+D35/60 -> 0.15000011 | F35: =(($C$7*($C$16/12)*(E35)^1.852)/($C$5^4.871)+L35)-G35 -> 0.0019273037 | G35: =$C$9*($C$16/12)/100 -> 0 | H35: =(B35*2.31)+F35-G35 -> 46.207525 | I35: =H35/2.31 -> 20.003257 | J35: =(1-1.27*0.05)*($D$26/((E35*60)/((A35/($C$16/12)+1)))) -> 0.93649934 | K35: =K34+(F35*0.433) -> 0.0032581369 | L35: =($C$11*((0.4085*E35/$C$5^2))^2)/64.4 -> 0.0013188669 | M35: =(L35/2.31)+M34 -> 0.0021981102 | N35: =($C$16/12)/(0.4085*E34/$C$5^2)+N34 -> 139.65938 | O35: =O34+$C$16/12 -> 9 | P35: =W34 -> 20.733835 | Q35: =S34 -> 1.6160703 | R35: =$C$17*W34^$C$18 -> 0.90064886 | S35: =Q35+R35/60 -> 1.6310811 | T35: =(($C$7*($C$16/12)*(S35)^1.852)/($C$5^4.871)+Z35)-U35 -> 0.20647985 | U35: =$C$9*($C$16/12)/100 -> 0 | V35: =(P35*2.31)+T35-U35 -> 48.10164 | W35: =V35/2.31 -> 20.823221 | Y35: =Y34+(T35*0.433) -> 0.82340992 | Z35: =($C$11*((0.4085*S35/$C$5^2))^2)/64.4 -> 0.15594411 | AA35: =(Z35/2.31)+AA34 -> 0.62080878 | AB35: =($C$16/12)/(0.4085*S34/$C$5^2)+AB34 -> 4.2857172
A36: =A35+$C$16/12 -> 10 | B36: =I35 -> 20.003257 | C36: =E35 -> 0.15000011 | D36: =$C$17*I35^$C$18 -> 0.90000293 | E36: =C36+D36/60 -> 0.16500016 | F36: =(($C$7*($C$16/12)*(E36)^1.852)/($C$5^4.871)+L36)-G36 -> 0.0023217265 | G36: =$C$9*($C$16/12)/100 -> 0 | H36: =(B36*2.31)+F36-G36 -> 46.209846 | I36: =H36/2.31 -> 20.004262 | J36: =(1-1.27*0.05)*($D$26/((E36*60)/((A36/($C$16/12)+1)))) -> 0.93649912 | K36: =K35+(F36*0.433) -> 0.0042634444 | L36: =($C$11*((0.4085*E36/$C$5^2))^2)/64.4 -> 0.0015958297 | M36: =(L36/2.31)+M35 -> 0.0028889456 | N36: =($C$16/12)/(0.4085*E35/$C$5^2)+N35 -> 144.59613 | O36: =O35+$C$16/12 -> 10 | P36: =W35 -> 20.823221 | Q36: =S35 -> 1.6310811 | R36: =$C$17*W35^$C$18 -> 0.90072635 | S36: =Q36+R36/60 -> 1.6460932 | T36: =(($C$7*($C$16/12)*(S36)^1.852)/($C$5^4.871)+Z36)-U36 -> 0.21022838 | U36: =$C$9*($C$16/12)/100 -> 0 | V36: =(P36*2.31)+T36-U36 -> 48.311868 | W36: =V36/2.31 -> 20.914229 | Y36: =Y35+(T36*0.433) -> 0.91443881 | Z36: =($C$11*((0.4085*S36/$C$5^2))^2)/64.4 -> 0.15882787 | AA36: =(Z36/2.31)+AA35 -> 0.68956543 | AB36: =($C$16/12)/(0.4085*S35/$C$5^2)+AB35 -> 4.7397191
A37: =A36+$C$16/12 -> 11 | B37: =I36 -> 20.004262 | C37: =E36 -> 0.16500016 | D37: =$C$17*I36^$C$18 -> 0.90000384 | E37: =C37+D37/60 -> 0.18000022 | F37: =(($C$7*($C$16/12)*(E37)^1.852)/($C$5^4.871)+L37)-G37 -> 0.0027519945 | G37: =$C$9*($C$16/12)/100 -> 0 | H37: =(B37*2.31)+F37-G37 -> 46.212598 | I37: =H37/2.31 -> 20.005454 | J37: =(1-1.27*0.05)*($D$26/((E37*60)/((A37/($C$16/12)+1)))) -> 0.93649886 | K37: =K36+(F37*0.433) -> 0.005455058 | L37: =($C$11*((0.4085*E37/$C$5^2))^2)/64.4 -> 0.0018991703 | M37: =(L37/2.31)+M36 -> 0.0037110972 | N37: =($C$16/12)/(0.4085*E36/$C$5^2)+N36 -> 149.08409 | O37: =O36+$C$16/12 -> 11 | P37: =W36 -> 20.914229 | Q37: =S36 -> 1.6460932 | R37: =$C$17*W36^$C$18 -> 0.90080491 | S37: =Q37+R37/60 -> 1.6611067 | T37: =(($C$7*($C$16/12)*(S37)^1.852)/($C$5^4.871)+Z37)-U37 -> 0.21401042 | U37: =$C$9*($C$16/12)/100 -> 0 | V37: =(P37*2.31)+T37-U37 -> 48.525878 | W37: =V37/2.31 -> 21.006874 | Y37: =Y36+(T37*0.433) -> 1.0071053 | Z37: =($C$11*((0.4085*S37/$C$5^2))^2)/64.4 -> 0.1617383 | AA37: =(Z37/2.31)+AA36 -> 0.75958201 | AB37: =($C$16/12)/(0.4085*S36/$C$5^2)+AB36 -> 5.1895807
A38: =A37+$C$16/12 -> 12 | B38: =I37 -> 20.005454 | C38: =E37 -> 0.18000022 | D38: =$C$17*I37^$C$18 -> 0.90000491 | E38: =C38+D38/60 -> 0.1950003 | F38: =(($C$7*($C$16/12)*(E38)^1.852)/($C$5^4.871)+L38)-G38 -> 0.0032179865 | G38: =$C$9*($C$16/12)/100 -> 0 | H38: =(B38*2.31)+F38-G38 -> 46.215816 | I38: =H38/2.31 -> 20.006847 | J38: =(1-1.27*0.05)*($D$26/((E38*60)/((A38/($C$16/12)+1)))) -> 0.93649856 | K38: =K37+(F38*0.433) -> 0.0068484462 | L38: =($C$11*((0.4085*E38/$C$5^2))^2)/64.4 -> 0.0022288888 | M38: =(L38/2.31)+M37 -> 0.0046759842 | N38: =($C$16/12)/(0.4085*E37/$C$5^2)+N37 -> 153.19806 | O38: =O37+$C$16/12 -> 12 | P38: =W37 -> 21.006874 | Q38: =S37 -> 1.6611067 | R38: =$C$17*W37^$C$18 -> 0.90088455 | S38: =Q38+R38/60 -> 1.6761214 | T38: =(($C$7*($C$16/12)*(S38)^1.852)/($C$5^4.871)+Z38)-U38 -> 0.21782595 | U38: =$C$9*($C$16/12)/100 -> 0 | V38: =(P38*2.31)+T38-U38 -> 48.743704 | W38: =V38/2.31 -> 21.101171 | Y38: =Y37+(T38*0.433) -> 1.101424 | Z38: =($C$11*((0.4085*S38/$C$5^2))^2)/64.4 -> 0.16467542 | AA38: =(Z38/2.31)+AA37 -> 0.83087007 | AB38: =($C$16/12)/(0.4085*S37/$C$5^2)+AB37 -> 5.6353763
A39: =A38+$C$16/12 -> 13 | B39: =I38 -> 20.006847 | C39: =E38 -> 0.1950003 | D39: =$C$17*I38^$C$18 -> 0.90000616 | E39: =C39+D39/60 -> 0.2100004 | F39: =(($C$7*($C$16/12)*(E39)^1.852)/($C$5^4.871)+L39)-G39 -> 0.0037195926 | G39: =$C$9*($C$16/12)/100 -> 0 | H39: =(B39*2.31)+F39-G39 -> 46.219536 | I39: =H39/2.31 -> 20.008457 | J39: =(1-1.27*0.05)*($D$26/((E39*60)/((A39/($C$16/12)+1)))) -> 0.9364982 | K39: =K38+(F39*0.433) -> 0.0084590298 | L39: =($C$11*((0.4085*E39/$C$5^2))^2)/64.4 -> 0.0025849854 | M39: =(L39/2.31)+M38 -> 0.0057950255 | N39: =($C$16/12)/(0.4085*E38/$C$5^2)+N38 -> 156.99556 | O39: =O38+$C$16/12 -> 13 | P39: =W38 -> 21.101171 | Q39: =S38 -> 1.6761214 | R39: =$C$17*W38^$C$18 -> 0.90096525 | S39: =Q39+R39/60 -> 1.6911375 | T39: =(($C$7*($C$16/12)*(S39)^1.852)/($C$5^4.871)+Z39)-U39 -> 0.22167499 | U39: =$C$9*($C$16/12)/100 -> 0 | V39: =(P39*2.31)+T39-U39 -> 48.965379 | W39: =V39/2.31 -> 21.197134 | Y39: =Y38+(T39*0.433) -> 1.1974092 | Z39: =($C$11*((0.4085*S39/$C$5^2))^2)/64.4 -> 0.16763924 | AA39: =(Z39/2.31)+AA38 -> 0.90344117 | AB39: =($C$16/12)/(0.4085*S38/$C$5^2)+AB38 -> 6.0771785
... A748: =A747+$C$16/12 -> 722 | B748: =I747 -> 970.12501 | C748: =E747 -> 11.240937 | D748: =$C$17*I747^$C$18 -> 0.97265419 | E748: =C748+D748/60 -> 11.257148 | F748: =(($C$7*($C$16/12)*(E748)^1.852)/($C$5^4.871)+L748)-G748 -> 9.2366317 | G748: =$C$9*($C$16/12)/100 -> 0 | H748: =(B748*2.31)+F748-G748 -> 2250.2254 | I748: =H748/2.31 -> 974.12355 | J748: =(1-1.27*0.05)*($D$26/((E748*60)/((A748/($C$16/12)+1)))) -> 0.90221279 | K748: =K747+(F748*0.433) -> 954.343 | L748: =($C$11*((0.4085*E748/$C$5^2))^2)/64.4 -> 7.4280456 | M748: =(L748/2.31)+M747 -> 759.47063 | N748: =($C$16/12)/(0.4085*E747/$C$5^2)+N747 -> 352.31751 | O748: =O747+$C$16/12 -> 722 | P748: =W747 -> 1417.9056 | Q748: =S747 -> 12.840964 | R748: =$C$17*W747^$C$18 -> 0.98006495 | S748: =Q748+R748/60 -> 12.857298 | T748: =(($C$7*($C$16/12)*(S748)^1.852)/($C$5^4.871)+Z748)-U748 -> 12.003193 | U748: =$C$9*($C$16/12)/100 -> 0 | V748: =(P748*2.31)+T748-U748 -> 3287.3652 | W748: =V748/2.31 -> 1423.1018 | Y748: =Y747+(T748*0.433) -> 1403.4245 | Z748: =($C$11*((0.4085*S748/$C$5^2))^2)/64.4 -> 9.6898548 | AA748: =(Z748/2.31)+AA747 -> 1121.4332 | AB748: =($C$16/12)/(0.4085*S747/$C$5^2)+AB747 -> 103.03962
O749: =O748+$C$16/12 -> 723 | P749: =W748 -> 1423.1018 | Q749: =S748 -> 12.857298 | R749: =$C$17*W748^$C$18 -> 0.98013665 | S749: =Q749+R749/60 -> 12.873634 | T749: =(($C$7*($C$16/12)*(S749)^1.852)/($C$5^4.871)+Z749)-U749 -> 12.033277 | U749: =$C$9*($C$16/12)/100 -> 0 | V749: =(P749*2.31)+T749-U749 -> 3299.3985 | W749: =V749/2.31 -> 1428.311 | Y749: =Y748+(T749*0.433) -> 1408.6349 | Z749: =($C$11*((0.4085*S749/$C$5^2))^2)/64.4 -> 9.714493 | AA749: =(Z749/2.31)+AA748 -> 1125.6386 | AB749: =($C$16/12)/(0.4085*S748/$C$5^2)+AB748 -> 103.09721
O750: =O749+$C$16/12 -> 724 | P750: =W749 -> 1428.311 | Q750: =S749 -> 12.873634 | R750: =$C$17*W749^$C$18 -> 0.98020828 | S750: =Q750+R750/60 -> 12.889971 | T750: =(($C$7*($C$16/12)*(S750)^1.852)/($C$5^4.871)+Z750)-U750 -> 12.063401 | U750: =$C$9*($C$16/12)/100 -> 0 | V750: =(P750*2.31)+T750-U750 -> 3311.4619 | W750: =V750/2.31 -> 1433.5333 | Y750: =Y749+(T750*0.433) -> 1413.8584 | Z750: =($C$11*((0.4085*S750/$C$5^2))^2)/64.4 -> 9.7391643 | AA750: =(Z750/2.31)+AA749 -> 1129.8547 | AB750: =($C$16/12)/(0.4085*S749/$C$5^2)+AB749 -> 103.15473
O751: =O750+$C$16/12 -> 725 | P751: =W750 -> 1433.5333 | Q751: =S750 -> 12.889971 | R751: =$C$17*W750^$C$18 -> 0.98027983 | S751: =Q751+R751/60 -> 12.906309 | T751: =(($C$7*($C$16/12)*(S751)^1.852)/($C$5^4.871)+Z751)-U751 -> 12.093565 | U751: =$C$9*($C$16/12)/100 -> 0 | V751: =(P751*2.31)+T751-U751 -> 3323.5555 | W751: =V751/2.31 -> 1438.7686 | Y751: =Y750+(T751*0.433) -> 1419.0949 | Z751: =($C$11*((0.4085*S751/$C$5^2))^2)/64.4 -> 9.7638687 | AA751: =(Z751/2.31)+AA750 -> 1134.0815 | AB751: =($C$16/12)/(0.4085*S750/$C$5^2)+AB750 -> 103.21218
...

Sheet Headworks Data
A2: ='[1]Required Inputs'!A3 -> G-WHWSGUT-D-15FA | B2: Headworks
A3: ='[1]Zone Valves Data'!B3 -> 15.75 | B3: Disposal Q
A4: ='[1]Zone Valves Data'!B4 -> 20.933599 | B4: Flushing Q
A5: ='[1]Zone Valves Data'!B5 -> 5.1835985 | B5: Return Q
B7: Headworks Part # | C7: Maximum GPM | D7: Supply | E7: Return | F7: Description
B8: G-WHWRS-D150A | C8: 20 | D8: 7 | E8: =Table6[[#This Row],[Supply]] -> 7 | F8: Vertical In Tank Headworks, 1.5" BioDisc Auto, Easy disconnect from riser,Auto Flush
B9: G-WHWRS-D150M | C9: 20 | D9: 5 | E9: =Table6[[#This Row],[Supply]] -> 5 | F9: Vertical In Tank Headwork, 1.5" BioDisc filter Manual, Easy disconnect from riser
B10: G-WHWSGUT-D-15FA | C10: 20 | D10: 7 | E10: =Table6[[#This Row],[Supply]] -> 7 | F10: Sporty Headworks Guts 1.5", BioDisc filter, surface flush,1" solenoid field + filter flush
B11: G-WHWSGUT-D-15FM | C11: 20 | D11: 5 | E11: =Table6[[#This Row],[Supply]] -> 5 | F11: Sporty Headworks Guts 1.5", BioDisc filter, manual flush,
B12: G-WHWSGUT-D-15ACT | C12: 20 | D12: 7 | E12: =Table6[[#This Row],[Supply]] -> 7 | F12: Sporty Headworks Guts 1.5", BioDisc filter -solenoid flus, Field-actuated ball flush
B13: G-WHWSGUT-D-15FA2 | C13: 30 | D13: 7 | E13: =Table6[[#This Row],[Supply]] -> 7 | F13: Sporty Headworks Guts with, 2x 1.5in BioDisc filters ,, Auto surface flush
A15: Headworks | B15: G-WHWRS-D150A | C15: G-WHWRS-D150M | D15: G-WHWSGUT-D-15FA | E15: G-WHWSGUT-D-15FM | F15: G-WHWSGUT-D-15ACT | G15: G-WHWSGUT-D-15FA2
A16: Disposal | B16: =LOOKUP($A$3,A22:A81,B22:B81) -> 5.64 | C16: =LOOKUP($A$3,$A$22:$A$81,C22:C81) -> 1 | D16: =LOOKUP($A$3,$A$22:$A$81,D22:D81) -> 5.64 | E16: =LOOKUP($A$3,$A$22:$A$81,E22:E81) -> 1 | F16: =LOOKUP($A$3,$A$22:$A$81,F22:F81) -> 1 | G16: =LOOKUP($A$3,$A$22:$A$81,G22:G81) -> 5.64
A17: Flushing | B17: =LOOKUP($A$4,A22:A81,B22:B81) -> 6.3 | C17: =LOOKUP($A$4,A22:A81,C22:C81) -> 1 | D17: =LOOKUP($A$4,A22:A81,D22:D81) -> 6.3 | E17: =LOOKUP($A$4,A22:A81,E22:E81) -> 1 | F17: =LOOKUP($A$4,A22:A81,F22:F81) -> 1 | G17: =LOOKUP($A$3,$A$22:$A$81,G22:G81) -> 5.64
A18: Return | B18: =LOOKUP($A$5,A23:A82,B23:B82) -> 4.6 | C18: =LOOKUP($A$5,A22:A81,C22:C81) -> 1 | D18: =LOOKUP($A$5,A22:A81,D22:D81) -> 4.6 | E18: =LOOKUP($A$5,A22:A81,E22:E81) -> 1 | F18: =LOOKUP($A$5,A22:A81,F22:F81) -> 1 | G18: =LOOKUP($A$5,A22:A81,G22:G81) -> 4.6
A21: gpm | B21: G-WHWRS-D150A | C21: G-WHWRS-D150M | D21: G-WHWSGUT-D-15FA | E21: G-WHWSGUT-D-15FM | F21: G-WHWSGUT-D-15ACT | G21: G-WHWSGUT-D-15FA2
A22: 1 | B22: 4.6 | C22: 1 | D22: =B22 -> 4.6 | E22: 1 | F22: 1 | G22: =D22 -> 4.6
A23: 2 | B23: 4.6 | C23: 1 | D23: =B23 -> 4.6 | E23: 1 | F23: 1 | G23: =D23 -> 4.6
A24: 3 | B24: 4.6 | C24: 1 | D24: =B24 -> 4.6 | E24: 1 | F24: 1 | G24: =D24 -> 4.6
A25: 4 | B25: 4.6 | C25: 1 | D25: =B25 -> 4.6 | E25: 1 | F25: 1 | G25: =D25 -> 4.6
A26: 5 | B26: 4.6 | C26: 1 | D26: =B26 -> 4.6 | E26: 1 | F26: 1 | G26: =D26 -> 4.6
A27: 6 | B27: 4.65 | C27: 1 | D27: =B27 -> 4.65 | E27: 1 | F27: 1 | G27: =D27 -> 4.65
A28: 7 | B28: 4.71 | C28: 1 | D28: =B28 -> 4.71 | E28: 1 | F28: 1 | G28: =D28 -> 4.71
A29: 8 | B29: 4.8 | C29: 1 | D29: =B29 -> 4.8 | E29: 1 | F29: 1 | G29: =D29 -> 4.8
A30: 9 | B30: 4.89 | C30: 1 | D30: =B30 -> 4.89 | E30: 1 | F30: 1 | G30: =D30 -> 4.89
A31: 10 | B31: 4.98 | C31: 1 | D31: =B31 -> 4.98 | E31: 1 | F31: 1 | G31: =D31 -> 4.98
A32: 11 | B32: =B31+0.132 -> 5.112 | C32: 1 | D32: =B32 -> 5.112 | E32: 1 | F32: 1 | G32: =D32 -> 5.112
A33: 12 | B33: =B32+0.132 -> 5.244 | C33: 1 | D33: =B33 -> 5.244 | E33: 1 | F33: 1 | G33: =D33 -> 5.244
A34: 13 | B34: =B33+0.132 -> 5.376 | C34: 1 | D34: =B34 -> 5.376 | E34: 1 | F34: 1 | G34: =D34 -> 5.376
A35: 14 | B35: =B34+0.132 -> 5.508 | C35: 1 | D35: =B35 -> 5.508 | E35: 1 | F35: 1 | G35: =D35 -> 5.508
A36: 15 | B36: =B35+0.132 -> 5.64 | C36: 1 | D36: =B36 -> 5.64 | E36: 1 | F36: 1 | G36: =D36 -> 5.64
A37: 16 | B37: =B36+0.132 -> 5.772 | C37: 1 | D37: =B37 -> 5.772 | E37: 1 | F37: 1 | G37: =D37 -> 5.772
A38: 17 | B38: =B37+0.132 -> 5.904 | C38: 1 | D38: =B38 -> 5.904 | E38: 1 | F38: 1 | G38: =D38 -> 5.904
A39: 18 | B39: =B38+0.132 -> 6.036 | C39: 1 | D39: =B39 -> 6.036 | E39: 1 | F39: 1 | G39: =D39 -> 6.036
A40: 19 | B40: =B39+0.132 -> 6.168 | C40: 1 | D40: =B40 -> 6.168 | E40: 1 | F40: 1 | G40: =D40 -> 6.168
A41: 20 | B41: =B40+0.132 -> 6.3 | C41: 1 | D41: =B41 -> 6.3 | E41: 1 | F41: 1 | G41: =D41 -> 6.3
A42: 21 | B42: =B41+0.24 -> 6.54 | C42: 1 | D42: =B42 -> 6.54 | E42: 1 | F42: 1 | G42: =D42 -> 6.54
A43: 22 | B43: =B42+0.24 -> 6.78 | C43: 1 | D43: =B43 -> 6.78 | E43: 1 | F43: 1 | G43: =D43 -> 6.78
A44: 23 | B44: =B43+0.24 -> 7.02 | C44: 1 | D44: =B44 -> 7.02 | E44: 1 | F44: 1 | G44: =D44 -> 7.02
A45: 24 | B45: =B44+0.24 -> 7.26 | C45: 1 | D45: =B45 -> 7.26 | E45: 1 | F45: 1 | G45: =D45 -> 7.26
...

Sheet Zone Valves Data
B2: ='[1]Required Inputs'!A4 -> G-HT-4404 | C2: Model #
B3: ='[1]Drip Tube Data'!C32 -> 15.75 | C3: Disposal Q
B4: ='[1]Drip Tube Data'!C34 -> 20.933599 | C4: Flushing Q
B5: =B4-B3 -> 5.1835985 | C5: Return Q
B7: Model | C7: 1 Zone | D7: G-HT-4402 | E7: G-HT-4403 | F7: G-HT-4404 | G7: G-HT-4602 | H7: G-HT-4603 | I7: G-HT-4604 | J7: G-HT-4605 | K7: G-HT-4606 | L7: G-SVLVB-100 | M7: G-SVLVB-150
B8: Disposal | C8: =C13 -> 0 | D8: =LOOKUP($B$3,$B$18:$B$197,D18:D197) -> 2.735 | E8: =LOOKUP($B$3,$B$18:$B$197,E18:E197) -> 2.735 | F8: =LOOKUP($B$3,$B$18:$B$197,F18:F197) -> 2.735 | G8: =LOOKUP($B$3,$B$18:$B$197,G18:G197) -> 3.335 | H8: =LOOKUP($B$3,$B$18:$B$197,H18:H197) -> 3.335 | I8: =LOOKUP($B$3,$B$18:$B$197,I18:I197) -> 3.335 | J8: =LOOKUP($B$3,$B$18:$B$197,J18:J197) -> 3.335 | K8: =LOOKUP($B$3,$B$18:$B$197,K18:K197) -> 3.335 | L8: =LOOKUP($B$3,$B$18:$B$197,T18:T197) -> 5.64 | M8: =LOOKUP($B$3,$B$18:$B$197,U18:U197) -> 4.5
B9: Flushing | C9: =C14 -> 0 | D9: =LOOKUP($B$4,$B$18:$B$197,D18:D197) -> 3.47 | E9: =LOOKUP($B$4,$B$18:$B$197,E18:E197) -> 3.47 | F9: =LOOKUP($B$4,$B$18:$B$197,F18:F197) -> 3.47 | G9: =LOOKUP($B$4,$B$18:$B$197,G18:G197) -> 4.17 | H9: =LOOKUP($B$4,$B$18:$B$197,H18:H197) -> 4.17 | I9: =LOOKUP($B$4,$B$18:$B$197,I18:I197) -> 4.17 | J9: =LOOKUP($B$4,$B$18:$B$197,J18:J197) -> 4.17 | K9: =LOOKUP($B$4,$B$18:$B$197,K18:K197) -> 4.17 | L9: =LOOKUP($B$4,$B$18:$B$197,T18:T197) -> 6.3 | M9: =LOOKUP($B$4,$B$18:$B$197,U18:U197) -> 4.7
A12: Model | C12: None | D12: G-HT-4402 | E12: G-HT-4403 | F12: G-HT-4404 | G12: G-HT-4602 | H12: G-HT-4603 | I12: G-HT-4604 | J12: G-HT-4605 | K12: G-HT-4606 | L12: 6402 | M12: 6403 | N12: 6404 | O12: 6602 | P12: 6603 | Q12: 6604 | R12: 6605 | S12: 6606 | T12: G-SVLVB-100 | U12: G-SVLVB-150
A13: Disposal | C13: =LOOKUP($B$3,$B$18:$B$197,C18:C197) -> 0 | D13: =LOOKUP($B$3,$B$18:$B$197,D18:D197) -> 2.735 | E13: =LOOKUP($B$3,$B$18:$B$197,E18:E197) -> 2.735 | F13: =LOOKUP($B$3,$B$18:$B$197,F18:F197) -> 2.735 | G13: =LOOKUP($B$3,$B$18:$B$197,G18:G197) -> 3.335 | H13: =LOOKUP($B$3,$B$18:$B$197,H18:H197) -> 3.335 | I13: =LOOKUP($B$3,$B$18:$B$197,I18:I197) -> 3.335 | J13: =LOOKUP($B$3,$B$18:$B$197,J18:J197) -> 3.335 | ... U13: =LOOKUP($B$3,$B$18:$B$197,U18:U197) -> 4.5
A14: Flushing | C14: =LOOKUP($B$4,$B$18:$B$197,C18:C197) -> 0 | D14: =LOOKUP($B$4,$B$18:$B$197,D18:D197) -> 3.47 | E14: =LOOKUP($B$4,$B$18:$B$197,E18:E197) -> 3.47 | F14: =LOOKUP($B$4,$B$18:$B$197,F18:F197) -> 3.47 | G14: =LOOKUP($B$4,$B$18:$B$197,G18:G197) -> 4.17 | H14: =LOOKUP($B$4,$B$18:$B$197,H18:H197) -> 4.17 | I14: =LOOKUP($B$4,$B$18:$B$197,I18:I197) -> 4.17 | J14: =LOOKUP($B$4,$B$18:$B$197,J18:J197) -> 4.17 | ... U14: =LOOKUP($B$4,$B$18:$B$197,U18:U197) -> 4.7
B17: GPM | C17: None | D17: G-HT-4402 | E17: G-HT-4403 | F17: G-HT-4404 | G17: G-HT-4602 | H17: G-HT-4603 | I17: G-HT-4604 | J17: G-HT-4605 | K17: G-HT-4606 | L17: 6402 | M17: 6403 | N17: 6404 | O17: 6602 | P17: 6603 | Q17: 6604 | R17: 6605 | S17: 6606 | T17: SVLVB-100 | U17: SVLVB-150 | V17: GPM
B18: 1 | C18: 0 | D18: Out of Range | E18: Out of Range | F18: Out of Range | G18: Out of Range | H18: Out of Range | I18: Out of Range | J18: Out of Range | K18: Out of Range | L18: Out of Range | M18: Out of Range | N18: Out of Range | O18: Out of Range | P18: Out of Range | Q18: Out of Range | R18: Out of Range | S18: Out of Range | T18: Out of Range | U18: Out of Range | V18: 1
B19: 2 | C19: 0 | D19: Out of Range | E19: Out of Range | F19: Out of Range | G19: Out of Range | H19: Out of Range | I19: Out of Range | J19: Out of Range | K19: Out of Range | L19: Out of Range | M19: Out of Range | N19: Out of Range | O19: Out of Range | P19: Out of Range | Q19: Out of Range | R19: Out of Range | S19: Out of Range | T19: Out of Range | U19: Out of Range | V19: 2
B20: 3 | C20: 0 | D20: Out of Range | E20: Out of Range | F20: Out of Range | G20: Out of Range | H20: Out of Range | I20: Out of Range | J20: Out of Range | K20: Out of Range | L20: Out of Range | M20: Out of Range | N20: Out of Range | O20: Out of Range | P20: Out of Range | Q20: Out of Range | R20: Out of Range | S20: Out of Range | T20: Out of Range | U20: Out of Range | V20: 3
B21: 4 | C21: 0 | D21: Out of Range | E21: Out of Range | F21: Out of Range | G21: Out of Range | H21: Out of Range | I21: Out of Range | J21: Out of Range | K21: Out of Range | L21: Out of Range | M21: Out of Range | N21: Out of Range | O21: Out of Range | P21: Out of Range | Q21: Out of Range | R21: Out of Range | S21: Out of Range | T21: Out of Range | U21: Out of Range | V21: 4
B22: 5 | C22: 0 | D22: Out of Range | E22: Out of Range | F22: Out of Range | G22: Out of Range | H22: Out of Range | I22: Out of Range | J22: Out of Range | K22: Out of Range | L22: Out of Range | M22: Out of Range | N22: Out of Range | O22: Out of Range | P22: Out of Range | Q22: Out of Range | R22: Out of Range | S22: Out of Range | T22: 4.6 | U22: Out of Range | V22: 5
B23: 6 | C23: 0 | D23: 2 | E23: =D23 -> 2 | F23: =E23 -> 2 | G23: 2.5 | H23: 2.5 | I23: 2.5 | J23: 2.5 | K23: 2.5 | L23: 2.5 | M23: 2.5 | N23: 2.5 | O23: 3 | P23: 3 | Q23: 3 | R23: 3 | S23: 3 | T23: 4.65 | U23: Out of Range | V23: 6
B24: 7 | C24: 0 | D24: 2 | E24: =D24 -> 2 | F24: =E24 -> 2 | G24: 2.5 | H24: 2.5 | I24: 2.5 | J24: 2.5 | K24: 2.5 | L24: 2.5 | M24: 2.5 | N24: 2.5 | O24: 3 | P24: 3 | Q24: 3 | R24: 3 | S24: 3 | T24: 4.71 | U24: Out of Range | V24: 7
B25: 8 | C25: 0 | D25: 2 | E25: =D25 -> 2 | F25: =E25 -> 2 | G25: 2.5 | H25: 2.5 | I25: 2.5 | J25: 2.5 | K25: 2.5 | L25: 2.5 | M25: 2.5 | N25: 2.5 | O25: 3 | P25: 3 | Q25: 3 | R25: 3 | S25: 3 | T25: 4.8 | U25: Out of Range | V25: 8
B26: 9 | C26: 0 | D26: 2 | E26: =D26 -> 2 | F26: =E26 -> 2 | G26: 2.5 | H26: 2.5 | I26: 2.5 | J26: 2.5 | K26: 2.5 | L26: 2.5 | M26: 2.5 | N26: 2.5 | O26: 3 | P26: 3 | Q26: 3 | R26: 3 | S26: 3 | T26: 4.89 | U26: Out of Range | V26: 9
B27: 10 | C27: 0 | D27: 2 | E27: =D27 -> 2 | F27: =E27 -> 2 | G27: 2.5 | H27: 2.5 | I27: 2.5 | J27: 2.5 | K27: 2.5 | L27: 2.5 | M27: 2.5 | N27: 2.5 | O27: 3 | P27: 3 | Q27: 3 | R27: 3 | S27: 3 | T27: 4.98 | U27: Out of Range | V27: 10
B28: 11 | C28: 0 | D28: =D27+0.147 -> 2.147 | E28: =D28 -> 2.147 | F28: =E28 -> 2.147 | G28: =G27+0.167 -> 2.667 | H28: =H27+0.167 -> 2.667 | I28: =I27+0.167 -> 2.667 | J28: =J27+0.167 -> 2.667 | K28: =K27+0.167 -> 2.667 | L28: 2.5 | M28: 2.5 | N28: 2.5 | O28: 3 | P28: 3 | Q28: 3 | R28: 3 | S28: 3 | T28: =T27+0.132 -> 5.112 | U28: Out of Range | V28: 11
